Workbook

Sheet Analysis
A1: =pv_only!A1 -> state_long | B1: =pv_only!B1 -> state_short | C1: =pv_only!C1 -> utility | D1: =pv_only!D1 -> building_id | E1: =pv_only!E1 -> latitude | F1: =pv_only!F1 -> longitude | G1: =pv_only!G1 -> year | H1: =pv_only!H1 -> run_type | I1: savings pv only | J1: Savings w batt | L1: Savings Diff no batt | M1: Savings Diff batt | N1: annual_energy | P1: Annual Energy diff
A2: =pv_only!A2 -> alabama | B2: =pv_only!B2 -> AL | C2: =pv_only!C2 -> apc | D2: =pv_only!D2 -> 46496 | E2: =pv_only!E2 -> 33.56 | F2: =pv_only!F2 -> -86.75 | G2: =pv_only!G2 -> 2018 | H2: =pv_only!H2 -> tmy | I2: {=pv_only!I2:I145} -> 823.29277 | J2: {=pv_plus_batt!I2:I145} -> 994.17436 | K2: =J2-I2 -> 170.88159 | N2: 9041.8682
A3: =pv_only!A3 -> alabama | B3: =pv_only!B3 -> AL | C3: =pv_only!C3 -> apc | D3: =pv_only!D3 -> 46496 | E3: =pv_only!E3 -> 33.56 | F3: =pv_only!F3 -> -86.75 | G3: =pv_only!G3 -> 2018 | H3: =pv_only!H3 -> amy | I3: 822.24787 | J3: 978.21772 | K3: =J3-I3 -> 155.96985 | L3: =(I3-I2)/I2 -> -0.0012691723 | M3: =(J3-J2)/J2 -> -0.016050146 | N3: 8621.1306 | P3: =(N3-N2)/N2 -> -0.046532156
A4: =pv_only!A4 -> alabama | B4: =pv_only!B4 -> AL | C4: =pv_only!C4 -> apc | D4: =pv_only!D4 -> 46496 | E4: =pv_only!E4 -> 33.56 | F4: =pv_only!F4 -> -86.75 | G4: =pv_only!G4 -> 2019 | H4: =pv_only!H4 -> tmy | I4: 830.35446 | J4: 998.44839 | K4: =J4-I4 -> 168.09393 | N4: 9041.8682
A5: =pv_only!A5 -> alabama | B5: =pv_only!B5 -> AL | C5: =pv_only!C5 -> apc | D5: =pv_only!D5 -> 46496 | E5: =pv_only!E5 -> 33.56 | F5: =pv_only!F5 -> -86.75 | G5: =pv_only!G5 -> 2019 | H5: =pv_only!H5 -> amy | I5: 844.01502 | J5: 997.14429 | K5: =J5-I5 -> 153.12927 | L5: =(I5-I4)/I4 -> 0.016451478 | M5: =(J5-J4)/J4 -> -0.001306125 | N5: 8716.7444 | P5: =(N5-N4)/N4 -> -0.035957593
A6: =pv_only!A6 -> alabama | B6: =pv_only!B6 -> AL | C6: =pv_only!C6 -> apc | D6: =pv_only!D6 -> 46496 | E6: =pv_only!E6 -> 33.56 | F6: =pv_only!F6 -> -86.75 | G6: =pv_only!G6 -> 2020 | H6: =pv_only!H6 -> tmy | I6: 784.22013 | J6: 979.25769 | K6: =J6-I6 -> 195.03756 | N6: 9041.8682
A7: =pv_only!A7 -> alabama | B7: =pv_only!B7 -> AL | C7: =pv_only!C7 -> apc | D7: =pv_only!D7 -> 46496 | E7: =pv_only!E7 -> 33.56 | F7: =pv_only!F7 -> -86.75 | G7: =pv_only!G7 -> 2020 | H7: =pv_only!H7 -> amy | I7: 786.96201 | J7: 973.85643 | K7: =J7-I7 -> 186.89443 | L7: =(I7-I6)/I6 -> 0.0034963065 | M7: =(J7-J6)/J6 -> -0.0055156665 | N7: 8634.7381 | P7: =(N7-N6)/N6 -> -0.045027216
A8: =pv_only!A8 -> alabama | B8: =pv_only!B8 -> AL | C8: =pv_only!C8 -> apc | D8: =pv_only!D8 -> 46496 | E8: =pv_only!E8 -> 33.56 | F8: =pv_only!F8 -> -86.75 | G8: =pv_only!G8 -> 2021 | H8: =pv_only!H8 -> tmy | I8: 777.19307 | J8: 993.54796 | K8: =J8-I8 -> 216.35489 | N8: 9041.8682
A9: =pv_only!A9 -> alabama | B9: =pv_only!B9 -> AL | C9: =pv_only!C9 -> apc | D9: =pv_only!D9 -> 46496 | E9: =pv_only!E9 -> 33.56 | F9: =pv_only!F9 -> -86.75 | G9: =pv_only!G9 -> 2021 | H9: =pv_only!H9 -> amy | I9: 767.47674 | J9: 980.78652 | K9: =J9-I9 -> 213.30978 | L9: =(I9-I8)/I8 -> -0.012501819 | M9: =(J9-J8)/J8 -> -0.012844315 | N9: 8847.2704 | P9: =(N9-N8)/N8 -> -0.021521865
A10: =pv_only!A10 -> alabama | B10: =pv_only!B10 -> AL | C10: =pv_only!C10 -> apc | D10: =pv_only!D10 -> 46496 | E10: =pv_only!E10 -> 33.56 | F10: =pv_only!F10 -> -86.75 | G10: =pv_only!G10 -> 2022 | H10: =pv_only!H10 -> tmy | I10: 820.24182 | J10: 1009.8847 | K10: =J10-I10 -> 189.6429 | N10: 9041.8682
A11: =pv_only!A11 -> alabama | B11: =pv_only!B11 -> AL | C11: =pv_only!C11 -> apc | D11: =pv_only!D11 -> 46496 | E11: =pv_only!E11 -> 33.56 | F11: =pv_only!F11 -> -86.75 | G11: =pv_only!G11 -> 2022 | H11: =pv_only!H11 -> amy | I11: 870.89925 | J11: 1054.4249 | K11: =J11-I11 -> 183.52567 | L11: =(I11-I10)/I10 -> 0.061759146 | M11: =(J11-J10)/J10 -> 0.044104243 | N11: 9524.5165 | P11: =(N11-N10)/N10 -> 0.053379267
A12: =pv_only!A12 -> alabama | B12: =pv_only!B12 -> AL | C12: =pv_only!C12 -> apc | D12: =pv_only!D12 -> 46496 | E12: =pv_only!E12 -> 33.56 | F12: =pv_only!F12 -> -86.75 | G12: =pv_only!G12 -> 2023 | H12: =pv_only!H12 -> tmy | I12: 810.03416 | J12: 1003.4162 | K12: =J12-I12 -> 193.38207 | N12: 9041.8682
A13: =pv_only!A13 -> alabama | B13: =pv_only!B13 -> AL | C13: =pv_only!C13 -> apc | D13: =pv_only!D13 -> 46496 | E13: =pv_only!E13 -> 33.56 | F13: =pv_only!F13 -> -86.75 | G13: =pv_only!G13 -> 2023 | H13: =pv_only!H13 -> amy | I13: 844.2987 | J13: 1048.876 | K13: =J13-I13 -> 204.57732 | L13: =(I13-I12)/I12 -> 0.042300113 | M13: =(J13-J12)/J12 -> 0.045305008 | N13: 9250.2634 | P13: =(N13-N12)/N12 -> 0.023047802
A14: =pv_only!A14 -> arizona | B14: =pv_only!B14 -> AZ | C14: =pv_only!C14 -> aps | D14: =pv_only!D14 -> 112157 | E14: =pv_only!E14 -> 35.14 | F14: =pv_only!F14 -> -111.67 | G14: =pv_only!G14 -> 2018 | H14: =pv_only!H14 -> tmy | I14: 924.93943 | J14: 1117.027 | K14: =J14-I14 -> 192.08758 | N14: 11330.222
A15: =pv_only!A15 -> arizona | B15: =pv_only!B15 -> AZ | C15: =pv_only!C15 -> aps | D15: =pv_only!D15 -> 112157 | E15: =pv_only!E15 -> 35.14 | F15: =pv_only!F15 -> -111.67 | G15: =pv_only!G15 -> 2018 | H15: =pv_only!H15 -> amy | I15: 932.16998 | J15: 1256.1125 | K15: =J15-I15 -> 323.94248 | L15: =(I15-I14)/I14 -> 0.007817317 | M15: =(J15-J14)/J14 -> 0.12451395 | N15: 11312.076 | P15: =(N15-N14)/N14 -> -0.0016016171
A16: =pv_only!A16 -> arizona | B16: =pv_only!B16 -> AZ | C16: =pv_only!C16 -> aps | D16: =pv_only!D16 -> 112157 | E16: =pv_only!E16 -> 35.14 | F16: =pv_only!F16 -> -111.67 | G16: =pv_only!G16 -> 2019 | H16: =pv_only!H16 -> tmy | I16: 922.69192 | J16: 1187.0812 | K16: =J16-I16 -> 264.38929 | N16: 11330.222
A17: =pv_only!A17 -> arizona | B17: =pv_only!B17 -> AZ | C17: =pv_only!C17 -> aps | D17: =pv_only!D17 -> 112157 | E17: =pv_only!E17 -> 35.14 | F17: =pv_only!F17 -> -111.67 | G17: =pv_only!G17 -> 2019 | H17: =pv_only!H17 -> amy | I17: 929.0352 | J17: 1243.4978 | K17: =J17-I17 -> 314.46265 | L17: =(I17-I16)/I16 -> 0.0068747539 | M17: =(J17-J16)/J16 -> 0.047525508 | N17: 11336.787 | P17: =(N17-N16)/N16 -> 0.00057938209
A18: =pv_only!A18 -> arizona | B18: =pv_only!B18 -> AZ | C18: =pv_only!C18 -> aps | D18: =pv_only!D18 -> 112157 | E18: =pv_only!E18 -> 35.14 | F18: =pv_only!F18 -> -111.67 | G18: =pv_only!G18 -> 2020 | H18: =pv_only!H18 -> tmy | I18: 901.6978 | J18: 1089.0508 | K18: =J18-I18 -> 187.35297 | N18: 11330.222
A19: =pv_only!A19 -> arizona | B19: =pv_only!B19 -> AZ | C19: =pv_only!C19 -> aps | D19: =pv_only!D19 -> 112157 | E19: =pv_only!E19 -> 35.14 | F19: =pv_only!F19 -> -111.67 | G19: =pv_only!G19 -> 2020 | H19: =pv_only!H19 -> amy | I19: 965.44135 | J19: 1257.9989 | K19: =J19-I19 -> 292.55759 | L19: =(I19-I18)/I18 -> 0.070692804 | M19: =(J19-J18)/J18 -> 0.15513342 | N19: 11855.872 | P19: =(N19-N18)/N18 -> 0.046393588
A20: =pv_only!A20 -> arizona | B20: =pv_only!B20 -> AZ | C20: =pv_only!C20 -> aps | D20: =pv_only!D20 -> 112157 | E20: =pv_only!E20 -> 35.14 | F20: =pv_only!F20 -> -111.67 | G20: =pv_only!G20 -> 2021 | H20: =pv_only!H20 -> tmy | I20: 907.62167 | J20: 1202.0926 | K20: =J20-I20 -> 294.47095 | N20: 11330.222
A21: =pv_only!A21 -> arizona | B21: =pv_only!B21 -> AZ | C21: =pv_only!C21 -> aps | D21: =pv_only!D21 -> 112157 | E21: =pv_only!E21 -> 35.14 | F21: =pv_only!F21 -> -111.67 | G21: =pv_only!G21 -> 2021 | H21: =pv_only!H21 -> amy | I21: 940.08774 | J21: 1234.8489 | K21: =J21-I21 -> 294.76119 | L21: =(I21-I20)/I20 -> 0.035770487 | M21: =(J21-J20)/J20 -> 0.027249405 | N21: 11443.475 | P21: =(N21-N20)/N20 -> 0.0099956274
A22: =pv_only!A22 -> arizona | B22: =pv_only!B22 -> AZ | C22: =pv_only!C22 -> aps | D22: =pv_only!D22 -> 112157 | E22: =pv_only!E22 -> 35.14 | F22: =pv_only!F22 -> -111.67 | G22: =pv_only!G22 -> 2022 | H22: =pv_only!H22 -> tmy | I22: 910.24801 | J22: 1162.5621 | K22: =J22-I22 -> 252.31405 | N22: 11330.222
A23: =pv_only!A23 -> arizona | B23: =pv_only!B23 -> AZ | C23: =pv_only!C23 -> aps | D23: =pv_only!D23 -> 112157 | E23: =pv_only!E23 -> 35.14 | F23: =pv_only!F23 -> -111.67 | G23: =pv_only!G23 -> 2022 | H23: =pv_only!H23 -> amy | I23: 933.56028 | J23: 1264.5918 | K23: =J23-I23 -> 331.03156 | L23: =(I23-I22)/I22 -> 0.025610904 | M23: =(J23-J22)/J22 -> 0.087762877 | N23: 11395.422 | P23: =(N23-N22)/N22 -> 0.0057544895
A24: =pv_only!A24 -> arizona | B24: =pv_only!B24 -> AZ | C24: =pv_only!C24 -> aps | D24: =pv_only!D24 -> 112157 | E24: =pv_only!E24 -> 35.14 | F24: =pv_only!F24 -> -111.67 | G24: =pv_only!G24 -> 2023 | H24: =pv_only!H24 -> tmy | I24: 918.90438 | J24: 1129.6572 | K24: =J24-I24 -> 210.75285 | N24: 11330.222
A25: =pv_only!A25 -> arizona | B25: =pv_only!B25 -> AZ | C25: =pv_only!C25 -> aps | D25: =pv_only!D25 -> 112157 | E25: =pv_only!E25 -> 35.14 | F25: =pv_only!F25 -> -111.67 | G25: =pv_only!G25 -> 2023 | H25: =pv_only!H25 -> amy | I25: 940.0629 | J25: 1240.2759 | K25: =J25-I25 -> 300.21303 | L25: =(I25-I24)/I24 -> 0.023025812 | M25: =(J25-J24)/J24 -> 0.097922364 | N25: 11559.838 | P25: =(N25-N24)/N24 -> 0.020265749
A26: =pv_only!A26 -> california | B26: =pv_only!B26 -> CA | C26: =pv_only!C26 -> sdge | D26: =pv_only!D26 -> 111549 | E26: =pv_only!E26 -> 32.87 | F26: =pv_only!F26 -> -117.15 | G26: =pv_only!G26 -> 2018 | H26: =pv_only!H26 -> tmy | I26: 2784.0255 | J26: 3767.4565 | K26: =J26-I26 -> 983.43103 | N26: 11233.731
A27: =pv_only!A27 -> california | B27: =pv_only!B27 -> CA | C27: =pv_only!C27 -> sdge | D27: =pv_only!D27 -> 111549 | E27: =pv_only!E27 -> 32.87 | F27: =pv_only!F27 -> -117.15 | G27: =pv_only!G27 -> 2018 | H27: =pv_only!H27 -> amy | I27: 2839.1139 | J27: 3838.3936 | K27: =J27-I27 -> 999.27966 | L27: =(I27-I26)/I26 -> 0.019787342 | M27: =(J27-J26)/J26 -> 0.018828908 | N27: 11279.392 | P27: =(N27-N26)/N26 -> 0.0040645669
A28: =pv_only!A28 -> california | B28: =pv_only!B28 -> CA | C28: =pv_only!C28 -> sdge | D28: =pv_only!D28 -> 111549 | E28: =pv_only!E28 -> 32.87 | F28: =pv_only!F28 -> -117.15 | G28: =pv_only!G28 -> 2019 | H28: =pv_only!H28 -> tmy | I28: 2685.5703 | J28: 3638.7501 | K28: =J28-I28 -> 953.17989 | N28: 11233.731
A29: =pv_only!A29 -> california | B29: =pv_only!B29 -> CA | C29: =pv_only!C29 -> sdge | D29: =pv_only!D29 -> 111549 | E29: =pv_only!E29 -> 32.87 | F29: =pv_only!F29 -> -117.15 | G29: =pv_only!G29 -> 2019 | H29: =pv_only!H29 -> amy | I29: 2743.1949 | J29: 3743.768 | K29: =J29-I29 -> 1000.5731 | L29: =(I29-I28)/I28 -> 0.02145712 | M29: =(J29-J28)/J28 -> 0.028860971 | N29: 11166.953 | P29: =(N29-N28)/N28 -> -0.0059444365
A30: =pv_only!A30 -> california | B30: =pv_only!B30 -> CA | C30: =pv_only!C30 -> sdge | D30: =pv_only!D30 -> 111549 | E30: =pv_only!E30 -> 32.87 | F30: =pv_only!F30 -> -117.15 | G30: =pv_only!G30 -> 2020 | H30: =pv_only!H30 -> tmy | I30: 2872.3513 | J30: 3810.9385 | K30: =J30-I30 -> 938.58721 | N30: 11233.731
A31: =pv_only!A31 -> california | B31: =pv_only!B31 -> CA | C31: =pv_only!C31 -> sdge | D31: =pv_only!D31 -> 111549 | E31: =pv_only!E31 -> 32.87 | F31: =pv_only!F31 -> -117.15 | G31: =pv_only!G31 -> 2020 | H31: =pv_only!H31 -> amy | I31: 2983.9093 | J31: 3972.2484 | K31: =J31-I31 -> 988.33916 | L31: =(I31-I30)/I30 -> 0.038838559 | M31: =(J31-J30)/J30 -> 0.04232814 | N31: 11558.106 | P31: =(N31-N30)/N30 -> 0.028875019
A32: =pv_only!A32 -> california | B32: =pv_only!B32 -> CA | C32: =pv_only!C32 -> sdge | D32: =pv_only!D32 -> 111549 | E32: =pv_only!E32 -> 32.87 | F32: =pv_only!F32 -> -117.15 | G32: =pv_only!G32 -> 2021 | H32: =pv_only!H32 -> tmy | I32: 2751.509 | J32: 3732.307 | K32: =J32-I32 -> 980.79803 | N32: 11233.731
A33: =pv_only!A33 -> california | B33: =pv_only!B33 -> CA | C33: =pv_only!C33 -> sdge | D33: =pv_only!D33 -> 111549 | E33: =pv_only!E33 -> 32.87 | F33: =pv_only!F33 -> -117.15 | G33: =pv_only!G33 -> 2021 | H33: =pv_only!H33 -> amy | I33: 2807.6311 | J33: 3790.4331 | K33: =J33-I33 -> 982.80198 | L33: =(I33-I32)/I32 -> 0.020396848 | M33: =(J33-J32)/J32 -> 0.015573762 | N33: 11237.143 | P33: =(N33-N32)/N32 -> 0.00030369074
A34: =pv_only!A34 -> california | B34: =pv_only!B34 -> CA | C34: =pv_only!C34 -> sdge | D34: =pv_only!D34 -> 111549 | E34: =pv_only!E34 -> 32.87 | F34: =pv_only!F34 -> -117.15 | G34: =pv_only!G34 -> 2022 | H34: =pv_only!H34 -> tmy | I34: 2906.8232 | J34: 3867.317 | K34: =J34-I34 -> 960.49372 | N34: 11233.731
A35: =pv_only!A35 -> california | B35: =pv_only!B35 -> CA | C35: =pv_only!C35 -> sdge | D35: =pv_only!D35 -> 111549 | E35: =pv_only!E35 -> 32.87 | F35: =pv_only!F35 -> -117.15 | G35: =pv_only!G35 -> 2022 | H35: =pv_only!H35 -> amy | I35: 2980.7392 | J35: 3967.3848 | K35: =J35-I35 -> 986.64565 | L35: =(I35-I34)/I34 -> 0.025428434 | M35: =(J35-J34)/J34 -> 0.025875274 | N35: 11681.258 | P35: =(N35-N34)/N34 -> 0.03983773
A36: =pv_only!A36 -> california | B36: =pv_only!B36 -> CA | C36: =pv_only!C36 -> sdge | D36: =pv_only!D36 -> 111549 | E36: =pv_only!E36 -> 32.87 | F36: =pv_only!F36 -> -117.15 | G36: =pv_only!G36 -> 2023 | H36: =pv_only!H36 -> tmy | I36: 2573.964 | J36: 3522.818 | K36: =J36-I36 -> 948.85403 | N36: 11233.731
A37: =pv_only!A37 -> california | B37: =pv_only!B37 -> CA | C37: =pv_only!C37 -> sdge | D37: =pv_only!D37 -> 111549 | E37: =pv_only!E37 -> 32.87 | F37: =pv_only!F37 -> -117.15 | G37: =pv_only!G37 -> 2023 | H37: =pv_only!H37 -> amy | I37: 2576.9425 | J37: 3522.2172 | K37: =J37-I37 -> 945.27468 | L37: =(I37-I36)/I36 -> 0.0011571784 | M37: =(J37-J36)/J36 -> -0.00017054869 | N37: 10568.645 | P37: =(N37-N36)/N36 -> -0.059204439
A38: =pv_only!A38 -> colorado | B38: =pv_only!B38 -> CO | C38: =pv_only!C38 -> xcel | D38: =pv_only!D38 -> 126745 | E38: =pv_only!E38 -> 39.81 | F38: =pv_only!F38 -> -105.14 | G38: =pv_only!G38 -> 2018 | H38: =pv_only!H38 -> tmy | I38: 1432.293 | J38: 1499.6317 | K38: =J38-I38 -> 67.338727 | N38: 9971.3267
A39: =pv_only!A39 -> colorado | B39: =pv_only!B39 -> CO | C39: =pv_only!C39 -> xcel | D39: =pv_only!D39 -> 126745 | E39: =pv_only!E39 -> 39.81 | F39: =pv_only!F39 -> -105.14 | G39: =pv_only!G39 -> 2018 | H39: =pv_only!H39 -> amy | I39: 1463.1722 | J39: 1524.9971 | K39: =J39-I39 -> 61.824926 | L39: =(I39-I38)/I38 -> 0.021559246 | M39: =(J39-J38)/J38 -> 0.01691439 | N39: 10132.42 | P39: =(N39-N38)/N38 -> 0.016155623
A40: =pv_only!A40 -> colorado | B40: =pv_only!B40 -> CO | C40: =pv_only!C40 -> xcel | D40: =pv_only!D40 -> 126745 | E40: =pv_only!E40 -> 39.81 | F40: =pv_only!F40 -> -105.14 | G40: =pv_only!G40 -> 2019 | H40: =pv_only!H40 -> tmy | I40: 1432.293 | J40: 1496.7336 | K40: =J40-I40 -> 64.440551 | N40: 9971.3267
...

Sheet Analysis-TMY only
A1: state_long | B1: state_short | C1: utility | D1: building_id | E1: latitude | F1: longitude | G1: year | H1: run_type | I1: savings pv only | J1: Savings w batt | L1: annual_energy | M1: Savings Diff batt
A2: alabama | B2: AL | C2: apc | D2: 46496 | E2: 33.56 | F2: -86.75 | G2: 2018 | H2: tmy | I2: 823.29277 | J2: 994.17436 | K2: 170.88159 | L2: 9041.8682
A3: alabama | B3: AL | C3: apc | D3: 46496 | E3: 33.56 | F3: -86.75 | G3: 2019 | H3: tmy | I3: 830.35446 | J3: 998.44839 | K3: 168.09393 | L3: 9041.8682
A4: alabama | B4: AL | C4: apc | D4: 46496 | E4: 33.56 | F4: -86.75 | G4: 2020 | H4: tmy | I4: 784.22013 | J4: 979.25769 | K4: 195.03756 | L4: 9041.8682
A5: alabama | B5: AL | C5: apc | D5: 46496 | E5: 33.56 | F5: -86.75 | G5: 2021 | H5: tmy | I5: 777.19307 | J5: 993.54796 | K5: 216.35489 | L5: 9041.8682
A6: alabama | B6: AL | C6: apc | D6: 46496 | E6: 33.56 | F6: -86.75 | G6: 2022 | H6: tmy | I6: 820.24182 | J6: 1009.8847 | K6: 189.6429 | L6: 9041.8682
A7: alabama | B7: AL | C7: apc | D7: 46496 | E7: 33.56 | F7: -86.75 | G7: 2023 | H7: tmy | I7: 810.03416 | J7: 1003.4162 | K7: 193.38207 | L7: 9041.8682
A8: arizona | B8: AZ | C8: aps | D8: 112157 | E8: 35.14 | F8: -111.67 | G8: 2018 | H8: tmy | I8: 924.93943 | J8: 1117.027 | K8: 192.08758 | L8: 11330.222
A9: arizona | B9: AZ | C9: aps | D9: 112157 | E9: 35.14 | F9: -111.67 | G9: 2019 | H9: tmy | I9: 922.69192 | J9: 1187.0812 | K9: 264.38929 | L9: 11330.222
A10: arizona | B10: AZ | C10: aps | D10: 112157 | E10: 35.14 | F10: -111.67 | G10: 2020 | H10: tmy | I10: 901.6978 | J10: 1089.0508 | K10: 187.35297 | L10: 11330.222
A11: arizona | B11: AZ | C11: aps | D11: 112157 | E11: 35.14 | F11: -111.67 | G11: 2021 | H11: tmy | I11: 907.62167 | J11: 1202.0926 | K11: 294.47095 | L11: 11330.222
A12: arizona | B12: AZ | C12: aps | D12: 112157 | E12: 35.14 | F12: -111.67 | G12: 2022 | H12: tmy | I12: 910.24801 | J12: 1162.5621 | K12: 252.31405 | L12: 11330.222
A13: arizona | B13: AZ | C13: aps | D13: 112157 | E13: 35.14 | F13: -111.67 | G13: 2023 | H13: tmy | I13: 918.90438 | J13: 1129.6572 | K13: 210.75285 | L13: 11330.222
... A73: wisconsin | B73: WI | C73: we_energies | D73: 467842 | E73: 42.95 | F73: -87.9 | G73: 2023 | H73: tmy | I73: 1386.6047 | J73: 1387.0007 | K73: 0.39593905 | L73: 8292.5516

Sheet Analysis-AMY only
A1: state_long | B1: state_short | C1: utility | D1: building_id | E1: latitude | F1: longitude | G1: year | H1: run_type | I1: savings pv only | J1: Savings w batt | L1: Savings Diff no batt | M1: Savings Diff batt | N1: annual_load | O1: annual_energy
A2: alabama | B2: AL | C2: apc | D2: 46496 | E2: 33.56 | F2: -86.75 | G2: 2018 | H2: amy | I2: 822.24787 | J2: 978.21772 | K2: 155.96985 | L2: -0.0012691723 | M2: -0.016050146 | N2: 11472.695 | O2: 8621.1306
A3: alabama | B3: AL | C3: apc | D3: 46496 | E3: 33.56 | F3: -86.75 | G3: 2019 | H3: amy | I3: 844.01502 | J3: 997.14429 | K3: 153.12927 | L3: 0.016451478 | M3: -0.001306125 | N3: 11894.363 | O3: 8716.7444
A4: alabama | B4: AL | C4: apc | D4: 46496 | E4: 33.56 | F4: -86.75 | G4: 2020 | H4: amy | I4: 786.96201 | J4: 973.85643 | K4: 186.89443 | L4: 0.0034963065 | M4: -0.0055156665 | N4: 10144.622 | O4: 8634.7381
A5: alabama | B5: AL | C5: apc | D5: 46496 | E5: 33.56 | F5: -86.75 | G5: 2021 | H5: amy | I5: 767.47674 | J5: 980.78652 | K5: 213.30978 | L5: -0.012501819 | M5: -0.012844315 | N5: 9454.1004 | O5: 8847.2704
A6: alabama | B6: AL | C6: apc | D6: 46496 | E6: 33.56 | F6: -86.75 | G6: 2022 | H6: amy | I6: 870.89925 | J6: 1054.4249 | K6: 183.52567 | L6: 0.061759146 | M6: 0.044104243 | N6: 11166.917 | O6: 9524.5165
A7: alabama | B7: AL | C7: apc | D7: 46496 | E7: 33.56 | F7: -86.75 | G7: 2023 | H7: amy | I7: 844.2987 | J7: 1048.876 | K7: 204.57732 | L7: 0.042300113 | M7: 0.045305008 | N7: 10870.759 | O7: 9250.2634
A8: arizona | B8: AZ | C8: aps | D8: 112157 | E8: 35.14 | F8: -111.67 | G8: 2018 | H8: amy | I8: 932.16998 | J8: 1256.1125 | K8: 323.94248 | L8: 0.007817317 | M8: 0.12451395 | N8: 12406.597 | O8: 11312.076
A9: arizona | B9: AZ | C9: aps | D9: 112157 | E9: 35.14 | F9: -111.67 | G9: 2019 | H9: amy | I9: 929.0352 | J9: 1243.4978 | K9: 314.46265 | L9: 0.0068747539 | M9: 0.047525508 | N9: 12209.288 | O9: 11336.787
A10: arizona | B10: AZ | C10: aps | D10: 112157 | E10: 35.14 | F10: -111.67 | G10: 2020 | H10: amy | I10: 965.44135 | J10: 1257.9989 | K10: 292.55759 | L10: 0.070692804 | M10: 0.15513342 | N10: 13006.749 | O10: 11855.872
A11: arizona | B11: AZ | C11: aps | D11: 112157 | E11: 35.14 | F11: -111.67 | G11: 2021 | H11: amy | I11: 940.08774 | J11: 1234.8489 | K11: 294.76119 | L11: 0.035770487 | M11: 0.027249405 | N11: 12416.012 | O11: 11443.475
A12: arizona | B12: AZ | C12: aps | D12: 112157 | E12: 35.14 | F12: -111.67 | G12: 2022 | H12: amy | I12: 933.56028 | J12: 1264.5918 | K12: 331.03156 | L12: 0.025610904 | M12: 0.087762877 | N12: 12433.614 | O12: 11395.422
A13: arizona | B13: AZ | C13: aps | D13: 112157 | E13: 35.14 | F13: -111.67 | G13: 2023 | H13: amy | I13: 940.0629 | J13: 1240.2759 | K13: 300.21303 | L13: 0.023025812 | M13: 0.097922364 | N13: 12404.026 | O13: 11559.838
... A73: wisconsin | B73: WI | C73: we_energies | D73: 467842 | E73: 42.95 | F73: -87.9 | G73: 2023 | H73: amy | I73: 1353.0336 | J73: 1353.7599 | K73: 0.72629873 | L73: -0.024211046 | M73: -0.023965952 | N73: 10714.602 | O73: 8143.4266

Sheet Graphics
A1: PV Only | B1: Colorado TMY | C1: AMY/TMY | D1: Colorado AMY | E1: OH TMY | F1: AMY/TMY | G1: OH AMY | H1: CA TMY | I1: AMY/TMY | J1: CA AMY | K1: AZ TMY | L1: AMY/TMY | M1: AZ AMY | N1: AL TMY | P1: AL AMY
A2: Median | B2: =MEDIAN('Analysis-TMY only'!I20:I25) -> 1432.293 | D2: =MEDIAN('Analysis-AMY only'!I20:I25) -> 1479.2374 | E2: =MEDIAN('Analysis-TMY only'!I44:I49) -> 1285.5593 | G2: =MEDIAN('Analysis-AMY only'!I44:I49) -> 1298.0997 | H2: =MEDIAN('Analysis-TMY only'!I14:I19) -> 2767.7672 | J2: =MEDIAN('Analysis-AMY only'!I14:I19) -> 2823.3725 | K2: =MEDIAN('Analysis-TMY only'!I8:I13) -> 914.57619 | M2: =MEDIAN('Analysis-AMY only'!I8:I13) -> 936.81159 | N2: =MEDIAN('Analysis-TMY only'!I2:I7) -> 815.13799 | P2: =MEDIAN('Analysis-AMY only'!I2:I7) -> 833.13144
A3: 2018 | B3: ='Analysis-TMY only'!I20-Graphics!$B$2 -> 0 | C3: ='Analysis-AMY only'!I20-Graphics!$B$2 -> 30.879157 | D3: ='Analysis-AMY only'!I20-Graphics!D$2 -> -16.065229 | E3: ='Analysis-TMY only'!I44-Graphics!E$2 -> 6.1830071 | F3: ='Analysis-AMY only'!I44-Graphics!E$2 -> -46.132938 | G3: ='Analysis-AMY only'!I44-Graphics!G$2 -> -58.673333 | H3: ='Analysis-TMY only'!I14-Graphics!H$2 -> 16.258224 | I3: ='Analysis-AMY only'!I14-Graphics!H$2 -> 71.346689 | J3: ='Analysis-AMY only'!I14-Graphics!J$2 -> 15.741401 | K3: ='Analysis-TMY only'!I8-Graphics!K$2 -> 10.36324 | L3: ='Analysis-AMY only'!I8-Graphics!K$2 -> 17.593785 | M3: ='Analysis-AMY only'!I8-Graphics!M$2 -> -4.6416125 | N3: ='Analysis-TMY only'!I2-Graphics!N$2 -> 8.1547759 | O3: ='Analysis-AMY only'!I2-Graphics!N$2 -> 7.1098756 | P3: ='Analysis-AMY only'!I2-Graphics!P$2 -> -10.883576
A4: =A3+1 -> 2019 | B4: ='Analysis-TMY only'!I21-Graphics!$B$2 -> 0 | C4: ='Analysis-AMY only'!I21-Graphics!$B$2 -> 15.007433 | D4: ='Analysis-AMY only'!I21-Graphics!D$2 -> -31.936953 | E4: ='Analysis-TMY only'!I45-Graphics!E$2 -> 0.3328076 | F4: ='Analysis-AMY only'!I45-Graphics!E$2 -> 2.4080021 | G4: ='Analysis-AMY only'!I45-Graphics!G$2 -> -10.132393 | H4: ='Analysis-TMY only'!I15-Graphics!H$2 -> -82.196984 | I4: ='Analysis-AMY only'!I15-Graphics!H$2 -> -24.572382 | J4: ='Analysis-AMY only'!I15-Graphics!J$2 -> -80.17767 | K4: ='Analysis-TMY only'!I9-Graphics!K$2 -> 8.1157288 | L4: ='Analysis-AMY only'!I9-Graphics!K$2 -> 14.459009 | M4: ='Analysis-AMY only'!I9-Graphics!M$2 -> -7.7763884 | N4: ='Analysis-TMY only'!I3-Graphics!N$2 -> 15.21647 | O4: ='Analysis-AMY only'!I3-Graphics!N$2 -> 28.877028 | P4: ='Analysis-AMY only'!I3-Graphics!P$2 -> 10.883576
A5: =A4+1 -> 2020 | B5: ='Analysis-TMY only'!I22-Graphics!$B$2 -> 0 | C5: ='Analysis-AMY only'!I22-Graphics!$B$2 -> 55.848396 | D5: ='Analysis-AMY only'!I22-Graphics!D$2 -> 8.9040099 | E5: ='Analysis-TMY only'!I46-Graphics!E$2 -> -0.80531324 | F5: ='Analysis-AMY only'!I46-Graphics!E$2 -> -51.749132 | G5: ='Analysis-AMY only'!I46-Graphics!G$2 -> -64.289527 | H5: ='Analysis-TMY only'!I16-Graphics!H$2 -> 104.58405 | I5: ='Analysis-AMY only'!I16-Graphics!H$2 -> 216.14204 | J5: ='Analysis-AMY only'!I16-Graphics!J$2 -> 160.53675 | K5: ='Analysis-TMY only'!I10-Graphics!K$2 -> -12.878392 | L5: ='Analysis-AMY only'!I10-Graphics!K$2 -> 50.865154 | M5: ='Analysis-AMY only'!I10-Graphics!M$2 -> 28.629757 | N5: ='Analysis-TMY only'!I4-Graphics!N$2 -> -30.917858 | O5: ='Analysis-AMY only'!I4-Graphics!N$2 -> -28.175984 | P5: ='Analysis-AMY only'!I4-Graphics!P$2 -> -46.169436
A6: =A5+1 -> 2021 | B6: ='Analysis-TMY only'!I23-Graphics!$B$2 -> 0 | C6: ='Analysis-AMY only'!I23-Graphics!$B$2 -> 62.826044 | D6: ='Analysis-AMY only'!I23-Graphics!D$2 -> 15.881658 | E6: ='Analysis-TMY only'!I47-Graphics!E$2 -> -0.71418038 | F6: ='Analysis-AMY only'!I47-Graphics!E$2 -> 35.783608 | G6: ='Analysis-AMY only'!I47-Graphics!G$2 -> 23.243213 | H6: ='Analysis-TMY only'!I17-Graphics!H$2 -> -16.258224 | I6: ='Analysis-AMY only'!I17-Graphics!H$2 -> 39.863886 | J6: ='Analysis-AMY only'!I17-Graphics!J$2 -> -15.741401 | K6: ='Analysis-TMY only'!I11-Graphics!K$2 -> -6.9545177 | L6: ='Analysis-AMY only'!I11-Graphics!K$2 -> 25.511552 | M6: ='Analysis-AMY only'!I11-Graphics!M$2 -> 3.2761548 | N6: ='Analysis-TMY only'!I5-Graphics!N$2 -> -37.944922 | O6: ='Analysis-AMY only'!I5-Graphics!N$2 -> -47.661249 | P6: ='Analysis-AMY only'!I5-Graphics!P$2 -> -65.654701
A7: =A6+1 -> 2022 | B7: ='Analysis-TMY only'!I24-Graphics!$B$2 -> 0 | C7: ='Analysis-AMY only'!I24-Graphics!$B$2 -> 62.786353 | D7: ='Analysis-AMY only'!I24-Graphics!D$2 -> 15.841967 | E7: ='Analysis-TMY only'!I48-Graphics!E$2 -> 2.9821762 | F7: ='Analysis-AMY only'!I48-Graphics!E$2 -> 45.060826 | G7: ='Analysis-AMY only'!I48-Graphics!G$2 -> 32.520431 | H7: ='Analysis-TMY only'!I18-Graphics!H$2 -> 139.056 | I7: ='Analysis-AMY only'!I18-Graphics!H$2 -> 212.97196 | J7: ='Analysis-AMY only'!I18-Graphics!J$2 -> 157.36667 | K7: ='Analysis-TMY only'!I12-Graphics!K$2 -> -4.3281863 | L7: ='Analysis-AMY only'!I12-Graphics!K$2 -> 18.984088 | M7: ='Analysis-AMY only'!I12-Graphics!M$2 -> -3.251309 | N7: ='Analysis-TMY only'!I6-Graphics!N$2 -> 5.103826 | O7: ='Analysis-AMY only'!I6-Graphics!N$2 -> 55.76126 | P7: ='Analysis-AMY only'!I6-Graphics!P$2 -> 37.767808
A8: =A7+1 -> 2023 | B8: ='Analysis-TMY only'!I25-Graphics!$B$2 -> 0 | C8: ='Analysis-AMY only'!I25-Graphics!$B$2 -> 38.040376 | D8: ='Analysis-AMY only'!I25-Graphics!D$2 -> -8.9040099 | E8: ='Analysis-TMY only'!I49-Graphics!E$2 -> -0.3328076 | F8: ='Analysis-AMY only'!I49-Graphics!E$2 -> 22.672788 | G8: ='Analysis-AMY only'!I49-Graphics!G$2 -> 10.132393 | H8: ='Analysis-TMY only'!I19-Graphics!H$2 -> -193.80324 | I8: ='Analysis-AMY only'!I19-Graphics!H$2 -> -190.82471 | J8: ='Analysis-AMY only'!I19-Graphics!J$2 -> -246.42999 | K8: ='Analysis-TMY only'!I13-Graphics!K$2 -> 4.3281863 | L8: ='Analysis-AMY only'!I13-Graphics!K$2 -> 25.486706 | M8: ='Analysis-AMY only'!I13-Graphics!M$2 -> 3.251309 | N8: ='Analysis-TMY only'!I7-Graphics!N$2 -> -5.103826 | O8: ='Analysis-AMY only'!I7-Graphics!N$2 -> 29.160711 | P8: ='Analysis-AMY only'!I7-Graphics!P$2 -> 11.167259
A10: 2018 | B10: =B3/B$2 -> 0 | C10: =C3/B$2 -> 0.021559246 | D10: =D3/D$2 -> -0.01086048 | E10: =E3/E$2 -> 0.0048095852 | F10: =F3/E$2 -> -0.0358855 | G10: =G3/G$2 -> -0.045199404 | H10: =H3/H$2 -> 0.0058741297 | I10: =I3/H$2 -> 0.025777705 | J10: =J3/J$2 -> 0.0055753893 | K10: =K3/K$2 -> 0.011331194 | L10: =L3/K$2 -> 0.01923709 | M10: =M3/M$2 -> -0.0049546916 | N10: =N3/N$2 -> 0.010004166 | O10: =O3/N$2 -> 0.0087222969 | P10: =P3/P$2 -> -0.013063456
A11: =A10+1 -> 2019 | B11: =B4/B$2 -> 0 | C11: =C4/B$2 -> 0.010477907 | D11: =D4/D$2 -> -0.021590147 | E11: =E4/E$2 -> 0.00025888156 | F11: =F4/E$2 -> 0.0018731163 | G11: =G4/G$2 -> -0.0078055582 | H11: =H4/H$2 -> -0.029697939 | I11: =I4/H$2 -> -0.0088780522 | J11: =J4/J$2 -> -0.028397836 | K11: =K4/K$2 -> 0.0088737591 | L11: =L4/K$2 -> 0.015809518 | M11: =M4/M$2 -> -0.0083009097 | N11: =N4/N$2 -> 0.018667354 | O11: =O4/N$2 -> 0.035425938 | P11: =P4/P$2 -> 0.013063456
A12: =A11+1 -> 2020 | B12: =B5/B$2 -> 0 | C12: =C5/B$2 -> 0.038992298 | D12: =D5/D$2 -> 0.0060193244 | E12: =E5/E$2 -> -0.00062643025 | F12: =F5/E$2 -> -0.040254177 | G12: =G5/G$2 -> -0.049525877 | H12: =H5/H$2 -> 0.037786433 | I12: =I5/H$2 -> 0.078092563 | J12: =J5/J$2 -> 0.056859925 | K12: =K5/K$2 -> -0.014081268 | L12: =L5/K$2 -> 0.055616092 | M12: =M5/M$2 -> 0.030560848 | N12: =N5/N$2 -> -0.0379296 | O12: =O5/N$2 -> -0.034565907 | P12: =P5/P$2 -> -0.055416749
A13: =A12+1 -> 2021 | B13: =B6/B$2 -> 0 | C13: =C6/B$2 -> 0.04386396 | D13: =D6/D$2 -> 0.010736382 | E13: =E6/E$2 -> -0.00055554059 | F13: =F6/E$2 -> 0.02783505 | G13: =G6/G$2 -> 0.017905568 | H13: =H6/H$2 -> -0.0058741297 | I13: =I6/H$2 -> 0.014402904 | J13: =J6/J$2 -> -0.0055753893 | K13: =K6/K$2 -> -0.0076040878 | L13: =L6/K$2 -> 0.027894398 | M13: =M6/M$2 -> 0.0034971331 | N13: =N6/N$2 -> -0.046550305 | O13: =O6/N$2 -> -0.05847016 | P13: =P6/P$2 -> -0.078804733
A14: =A13+1 -> 2022 | B14: =B7/B$2 -> 0 | C14: =C7/B$2 -> 0.043836249 | D14: =D7/D$2 -> 0.01070955 | E14: =E7/E$2 -> 0.00231975 | F14: =F7/E$2 -> 0.035051534 | G14: =G7/G$2 -> 0.025052337 | H14: =H7/H$2 -> 0.050241217 | I14: =I7/H$2 -> 0.076947207 | J14: =J7/J$2 -> 0.055737126 | K14: =K7/K$2 -> -0.0047324502 | L14: =L7/K$2 -> 0.020757252 | M14: =M7/M$2 -> -0.0034706114 | N14: =N7/N$2 -> 0.006261303 | O14: =O7/N$2 -> 0.068407142 | P14: =P7/P$2 -> 0.045332352
A15: =A14+1 -> 2023 | B15: =B8/B$2 -> 0 | C15: =C8/B$2 -> 0.026559074 | D15: =D8/D$2 -> -0.0060193244 | E15: =E8/E$2 -> -0.00025888156 | F15: =F8/E$2 -> 0.017636516 | G15: =G8/G$2 -> 0.0078055582 | H15: =H8/H$2 -> -0.07002151 | I15: =I8/H$2 -> -0.068945359 | J15: =J8/J$2 -> -0.087282139 | K15: =K8/K$2 -> 0.0047324502 | L15: =L8/K$2 -> 0.027867231 | M15: =M8/M$2 -> 0.0034706114 | N15: =N8/N$2 -> -0.006261303 | O15: =O8/N$2 -> 0.035773956 | P15: =P8/P$2 -> 0.013403958
A16: Max diff | B16: {=MAX(ABS(B10:B15))} -> 0 | C16: {=MAX(ABS(C10:C15))} -> 0.04386396 | D16: {=MAX(ABS(D10:D15))} -> 0.021590147 | E16: {=MAX(ABS(E10:E15))} -> 0.0048095852 | F16: {=MAX(ABS(F10:F15))} -> 0.040254177 | G16: {=MAX(ABS(G10:G15))} -> 0.049525877 | H16: {=MAX(ABS(H10:H15))} -> 0.07002151 | I16: {=MAX(ABS(I10:I15))} -> 0.078092563 | ... P16: {=MAX(ABS(P10:P15))} -> 0.078804733
A17: Avg Diff | B17: =AVERAGE(B10:B15) -> 0 | C17: =AVERAGE(C10:C15) -> 0.030881456 | D17: =AVERAGE(D10:D15) -> -0.0018341159 | E17: =AVERAGE(E10:E15) -> 0.00099122739 | F17: =AVERAGE(F10:F15) -> 0.0010427566 | G17: =AVERAGE(G10:G15) -> -0.0086278961 | H17: =AVERAGE(H10:H15) -> -0.0019486331 | I17: =AVERAGE(I10:I15) -> 0.019566161 | ... P17: =AVERAGE(P10:P15) -> -0.012580862
A18: Avg Abs Err | B18: {=AVERAGE(ABS(B10:B15))} -> 0 | C18: {=AVERAGE(ABS(C10:C15))} -> 0.030881456 | D18: {=AVERAGE(ABS(D10:D15))} -> 0.010989201 | E18: {=AVERAGE(ABS(E10:E15))} -> 0.0014715115 | F18: {=AVERAGE(ABS(F10:F15))} -> 0.026422649 | G18: {=AVERAGE(ABS(G10:G15))} -> 0.025549051 | H18: {=AVERAGE(ABS(H10:H15))} -> 0.033249227 | I18: {=AVERAGE(ABS(I10:I15))} -> 0.045507298 | ... P18: {=AVERAGE(ABS(P10:P15))} -> 0.036514118
A20: W Batt | B20: Colorado TMY | C20: AMY/TMY | D20: Colorado AMY | E20: OH TMY | F20: AMY/TMY | G20: OH AMY | H20: CA TMY | I20: AMY/TMY | J20: CA AMY | K20: AZ TMY | L20: AMY/TMY | M20: AZ AMY
A21: Median | B21: =MEDIAN('Analysis-TMY only'!J20:J25) -> 1498.6327 | D21: =MEDIAN('Analysis-AMY only'!J20:J25) -> 1543.5125 | E21: =MEDIAN('Analysis-TMY only'!J44:J49) -> 1285.4296 | G21: =MEDIAN('Analysis-AMY only'!J44:J49) -> 1297.6331 | H21: =MEDIAN('Analysis-TMY only'!J14:J19) -> 3749.8818 | J21: =MEDIAN('Analysis-AMY only'!J14:J19) -> 3814.4133 | K21: =MEDIAN('Analysis-TMY only'!J8:J13) -> 1146.1096 | M21: =MEDIAN('Analysis-AMY only'!J8:J13) -> 1249.8052 | N21: =MEDIAN('Analysis-TMY only'!J2:J7) -> 996.31137 | P21: =MEDIAN('Analysis-AMY only'!J2:J7) -> 988.9654
A22: 2018 | B22: ='Analysis-TMY only'!J20-Graphics!$B$21 -> 0.999 | C22: ='Analysis-AMY only'!J20-Graphics!$B$21 -> 26.364356 | D22: ='Analysis-AMY only'!J20-Graphics!D$21 -> -18.515382 | E22: ='Analysis-TMY only'!J44-Graphics!E$21 -> 6.8193895 | F22: ='Analysis-AMY only'!J44-Graphics!E$21 -> -44.915761 | G22: ='Analysis-AMY only'!J44-Graphics!G$21 -> -57.119241 | H22: ='Analysis-TMY only'!J14-Graphics!H$21 -> 17.574724 | I22: ='Analysis-AMY only'!J14-Graphics!H$21 -> 88.511817 | J22: ='Analysis-AMY only'!J14-Graphics!J$21 -> 23.980239 | K22: ='Analysis-TMY only'!J8-Graphics!K$21 -> -29.082628 | L22: ='Analysis-AMY only'!J8-Graphics!K$21 -> 110.00282 | M22: ='Analysis-AMY only'!J8-Graphics!M$21 -> 6.3073055 | N22: ='Analysis-TMY only'!J2-Graphics!N$21 -> -2.1370143 | O22: ='Analysis-AMY only'!J2-Graphics!N$21 -> -18.093658 | P22: ='Analysis-AMY only'!J2-Graphics!N$21 -> -18.093658
A23: =A22+1 -> 2019 | B23: ='Analysis-TMY only'!J21-Graphics!$B$21 -> -1.899176 | C23: ='Analysis-AMY only'!J21-Graphics!$B$21 -> 9.81257 | D23: ='Analysis-AMY only'!J21-Graphics!D$21 -> -35.067168 | E23: ='Analysis-TMY only'!J45-Graphics!E$21 -> 0.1928125 | F23: ='Analysis-AMY only'!J45-Graphics!E$21 -> 2.9253215 | G23: ='Analysis-AMY only'!J45-Graphics!G$21 -> -9.278159 | H23: ='Analysis-TMY only'!J15-Graphics!H$21 -> -111.13162 | I23: ='Analysis-AMY only'!J15-Graphics!H$21 -> -6.1137605 | J23: ='Analysis-AMY only'!J15-Graphics!J$21 -> -70.645338 | K23: ='Analysis-TMY only'!J9-Graphics!K$21 -> 40.97157 | L23: ='Analysis-AMY only'!J9-Graphics!K$21 -> 97.388207 | M23: ='Analysis-AMY only'!J9-Graphics!M$21 -> -6.3073055 | N23: ='Analysis-TMY only'!J3-Graphics!N$21 -> 2.1370144 | O23: ='Analysis-AMY only'!J3-Graphics!N$21 -> 0.83291595 | P23: ='Analysis-AMY only'!J3-Graphics!N$21 -> 0.83291595
A24: =A23+1 -> 2020 | B24: ='Analysis-TMY only'!J22-Graphics!$B$21 -> 0.746739 | C24: ='Analysis-AMY only'!J22-Graphics!$B$21 -> 58.639515 | D24: ='Analysis-AMY only'!J22-Graphics!D$21 -> 13.759777 | E24: ='Analysis-TMY only'!J46-Graphics!E$21 -> -2.1644335 | F24: ='Analysis-AMY only'!J46-Graphics!E$21 -> -52.64553 | G24: ='Analysis-AMY only'!J46-Graphics!G$21 -> -64.84901 | H24: ='Analysis-TMY only'!J16-Graphics!H$21 -> 61.056734 | I24: ='Analysis-AMY only'!J16-Graphics!H$21 -> 222.36667 | J24: ='Analysis-AMY only'!J16-Graphics!J$21 -> 157.8351 | K24: ='Analysis-TMY only'!J10-Graphics!K$21 -> -57.058873 | L24: ='Analysis-AMY only'!J10-Graphics!K$21 -> 111.8893 | M24: ='Analysis-AMY only'!J10-Graphics!M$21 -> 8.1937865 | N24: ='Analysis-TMY only'!J4-Graphics!N$21 -> -17.053683 | O24: ='Analysis-AMY only'!J4-Graphics!N$21 -> -22.454941 | P24: ='Analysis-AMY only'!J4-Graphics!N$21 -> -22.454941
A25: =A24+1 -> 2021 | B25: ='Analysis-TMY only'!J23-Graphics!$B$21 -> 0.150508 | C25: ='Analysis-AMY only'!J23-Graphics!$B$21 -> 58.386155 | D25: ='Analysis-AMY only'!J23-Graphics!D$21 -> 13.506417 | E25: ='Analysis-TMY only'!J47-Graphics!E$21 -> -1.2328625 | F25: ='Analysis-AMY only'!J47-Graphics!E$21 -> 37.228867 | G25: ='Analysis-AMY only'!J47-Graphics!G$21 -> 25.025387 | H25: ='Analysis-TMY only'!J17-Graphics!H$21 -> -17.574725 | I25: ='Analysis-AMY only'!J17-Graphics!H$21 -> 40.551338 | J25: ='Analysis-AMY only'!J17-Graphics!J$21 -> -23.98024 | K25: ='Analysis-TMY only'!J11-Graphics!K$21 -> 55.98299 | L25: ='Analysis-AMY only'!J11-Graphics!K$21 -> 88.739299 | M25: ='Analysis-AMY only'!J11-Graphics!M$21 -> -14.956213 | N25: ='Analysis-TMY only'!J5-Graphics!N$21 -> -2.7634124 | O25: ='Analysis-AMY only'!J5-Graphics!N$21 -> -15.524855 | P25: ='Analysis-AMY only'!J5-Graphics!N$21 -> -15.524855
A26: =A25+1 -> 2022 | B26: ='Analysis-TMY only'!J24-Graphics!$B$21 -> -0.150508 | C26: ='Analysis-AMY only'!J24-Graphics!$B$21 -> 55.426553 | D26: ='Analysis-AMY only'!J24-Graphics!D$21 -> 10.546815 | E26: ='Analysis-TMY only'!J48-Graphics!E$21 -> 2.8122015 | F26: ='Analysis-AMY only'!J48-Graphics!E$21 -> 45.623114 | G26: ='Analysis-AMY only'!J48-Graphics!G$21 -> 33.419633 | H26: ='Analysis-TMY only'!J18-Graphics!H$21 -> 117.43519 | I26: ='Analysis-AMY only'!J18-Graphics!H$21 -> 217.50308 | J26: ='Analysis-AMY only'!J18-Graphics!J$21 -> 152.9715 | K26: ='Analysis-TMY only'!J12-Graphics!K$21 -> 16.452412 | L26: ='Analysis-AMY only'!J12-Graphics!K$21 -> 118.4822 | M26: ='Analysis-AMY only'!J12-Graphics!M$21 -> 14.786689 | N26: ='Analysis-TMY only'!J6-Graphics!N$21 -> 13.573341 | O26: ='Analysis-AMY only'!J6-Graphics!N$21 -> 58.113542 | P26: ='Analysis-AMY only'!J6-Graphics!N$21 -> 58.113542
A27: =A26+1 -> 2023 | B27: ='Analysis-TMY only'!J25-Graphics!$B$21 -> -2.215539 | C27: ='Analysis-AMY only'!J25-Graphics!$B$21 -> 34.332923 | D27: ='Analysis-AMY only'!J25-Graphics!D$21 -> -10.546815 | E27: ='Analysis-TMY only'!J49-Graphics!E$21 -> -0.1928125 | F27: ='Analysis-AMY only'!J49-Graphics!E$21 -> 21.48164 | G27: ='Analysis-AMY only'!J49-Graphics!G$21 -> 9.278159 | H27: ='Analysis-TMY only'!J19-Graphics!H$21 -> -227.06374 | I27: ='Analysis-AMY only'!J19-Graphics!H$21 -> -227.66455 | J27: ='Analysis-AMY only'!J19-Graphics!J$21 -> -292.19613 | K27: ='Analysis-TMY only'!J13-Graphics!K$21 -> -16.452412 | L27: ='Analysis-AMY only'!J13-Graphics!K$21 -> 94.166294 | M27: ='Analysis-AMY only'!J13-Graphics!M$21 -> -9.5292185 | N27: ='Analysis-TMY only'!J7-Graphics!N$21 -> 7.1048621 | O27: ='Analysis-AMY only'!J7-Graphics!N$21 -> 52.564643 | P27: ='Analysis-AMY only'!J7-Graphics!N$21 -> 52.564643
A29: 2018 | B29: =B22/B$21 -> 0.00066660761 | C29: =C22/B$21 -> 0.017592273 | D29: =D22/D$21 -> -0.011995615 | E29: =E22/E$21 -> 0.0053051441 | F29: =F22/E$21 -> -0.034942216 | G29: =G22/G$21 -> -0.04401802 | H29: =H22/H$21 -> 0.004686741 | I29: =I22/H$21 -> 0.023603896 | J29: =J22/J$21 -> 0.0062867438 | K29: =K22/K$21 -> -0.025375084 | L29: =L22/K$21 -> 0.095979315 | M29: =M22/M$21 -> 0.0050466311 | N29: =N22/N$21 -> -0.0021449262 | O29: =O22/N$21 -> -0.018160646 | P29: =P22/P$21 -> -0.018295542
A30: =A29+1 -> 2019 | B30: =B23/B$21 -> -0.0012672725 | C30: =C23/B$21 -> 0.0065476816 | D30: =D23/D$21 -> -0.02271907 | E30: =E23/E$21 -> 0.00014999849 | F30: =F23/E$21 -> 0.0022757539 | G30: =G23/G$21 -> -0.0071500634 | H30: =H23/H$21 -> -0.029636034 | I30: =I23/H$21 -> -0.0016303875 | J30: =J23/J$21 -> -0.01852063 | K30: =K23/K$21 -> 0.035748386 | L30: =L23/K$21 -> 0.084972854 | M30: =M23/M$21 -> -0.0050466311 | N30: =N23/N$21 -> 0.0021449262 | O30: =O23/N$21 -> 0.00083599964 | P30: =P23/P$21 -> 0.00084220939
A31: =A30+1 -> 2020 | B31: =B24/B$21 -> 0.00049828018 | C31: =C24/B$21 -> 0.039128676 | D31: =D24/D$21 -> 0.0089145874 | E31: =E24/E$21 -> -0.0016838211 | F31: =F24/E$21 -> -0.04095559 | G31: =G24/G$21 -> -0.049974842 | H31: =H24/H$21 -> 0.016282309 | I31: =I24/H$21 -> 0.059299649 | J31: =J24/J$21 -> 0.041378603 | K31: =K24/K$21 -> -0.04978483 | L31: =L24/K$21 -> 0.097625301 | M31: =M24/M$21 -> 0.0065560511 | N31: =N24/N$21 -> -0.01711682 | O31: =O24/N$21 -> -0.022538076 | P31: =P24/P$21 -> -0.022705487
A32: =A31+1 -> 2021 | B32: =B25/B$21 -> 0.00010043021 | C32: =C25/B$21 -> 0.038959615 | D32: =D25/D$21 -> 0.0087504423 | E32: =E25/E$21 -> -0.0009591054 | F32: =F25/E$21 -> 0.028962198 | G32: =G25/G$21 -> 0.01928541 | H32: =H25/H$21 -> -0.004686741 | I32: =I25/H$21 -> 0.010814031 | J32: =J25/J$21 -> -0.0062867438 | K32: =K25/K$21 -> 0.048846103 | L32: =L25/K$21 -> 0.077426536 | M32: =M25/M$21 -> -0.011966836 | N32: =N25/N$21 -> -0.0027736434 | O32: =O25/N$21 -> -0.015582332 | P32: =P25/P$21 -> -0.015698077
A33: =A32+1 -> 2022 | B33: =B26/B$21 -> -0.00010043021 | C33: =C26/B$21 -> 0.036984747 | D33: =D26/D$21 -> 0.0068329962 | E33: =E26/E$21 -> 0.0021877522 | F33: =F26/E$21 -> 0.035492502 | G33: =G26/G$21 -> 0.0257543 | H33: =H26/H$21 -> 0.031317039 | I33: =I26/H$21 -> 0.05800265 | J33: =J26/J$21 -> 0.040103546 | K33: =K26/K$21 -> 0.014355007 | L33: =L26/K$21 -> 0.10337772 | M33: =M26/M$21 -> 0.011831196 | N33: =N26/N$21 -> 0.013623593 | O33: =O26/N$21 -> 0.058328695 | P33: =P26/P$21 -> 0.058761956
A34: =A33+1 -> 2023 | B34: =B27/B$21 -> -0.0014783735 | C34: =C27/B$21 -> 0.022909497 | D34: =D27/D$21 -> -0.0068329962 | E34: =E27/E$21 -> -0.00014999849 | F34: =F27/E$21 -> 0.016711642 | G34: =G27/G$21 -> 0.0071500634 | H34: =H27/H$21 -> -0.06055224 | I34: =I27/H$21 -> -0.060712461 | J34: =J27/J$21 -> -0.076603164 | K34: =K27/K$21 -> -0.014355007 | L34: =L27/K$21 -> 0.082161681 | M34: =M27/M$21 -> -0.0076245633 | N34: =N27/N$21 -> 0.0071311663 | O34: =O27/N$21 -> 0.052759252 | P34: =P27/P$21 -> 0.053151144
A35: Max diff | B35: {=MAX(ABS(B29:B34))} -> 0.0014783735 | C35: {=MAX(ABS(C29:C34))} -> 0.039128676 | D35: {=MAX(ABS(D29:D34))} -> 0.02271907 | E35: {=MAX(ABS(E29:E34))} -> 0.0053051441 | F35: {=MAX(ABS(F29:F34))} -> 0.04095559 | G35: {=MAX(ABS(G29:G34))} -> 0.049974842 | H35: {=MAX(ABS(H29:H34))} -> 0.06055224 | I35: {=MAX(ABS(I29:I34))} -> 0.060712461 | ... P35: {=MAX(ABS(P29:P34))} -> 0.058761956
A36: Avg Diff | B36: =AVERAGE(B29:B34) -> -0.0002634597 | C36: =AVERAGE(C29:C34) -> 0.027020415 | D36: =AVERAGE(D29:D34) -> -0.0028416092 | E36: =AVERAGE(E29:E34) -> 0.00080832831 | F36: =AVERAGE(F29:F34) -> 0.0012573814 | G36: =AVERAGE(G29:G34) -> -0.0081588586 | H36: =AVERAGE(H29:H34) -> -0.0070981542 | I36: =AVERAGE(I29:I34) -> 0.01489623 | ... P36: =AVERAGE(P29:P34) -> 0.0093427006
A37: Avg Abs Err | B37: {=AVERAGE(ABS(B29:B34))} -> 0.00068523237 | C37: {=AVERAGE(ABS(C29:C34))} -> 0.027020415 | D37: {=AVERAGE(ABS(D29:D34))} -> 0.011007618 | E37: {=AVERAGE(ABS(E29:E34))} -> 0.0017393033 | F37: {=AVERAGE(ABS(F29:F34))} -> 0.02655665 | G37: {=AVERAGE(ABS(G29:G34))} -> 0.02555545 | H37: {=AVERAGE(ABS(H29:H34))} -> 0.024526851 | I37: {=AVERAGE(ABS(I29:I34))} -> 0.035677179 | ... P37: {=AVERAGE(ABS(P29:P34))} -> 0.028242403
A39: Load Diffs | B39: CO | C39: OH | D39: CA | E39: AZ
A40: Median | B40: =MEDIAN('Analysis-AMY only'!N20:N25) -> 11058.065 | C40: =MEDIAN('Analysis-AMY only'!N44:N49) -> 10340.517 | D40: =MEDIAN('Analysis-AMY only'!N14:N19) -> 10887.383 | E40: =MEDIAN('Analysis-AMY only'!N8:N13) -> 12411.304
A41: 2018 | B41: ='Analysis-AMY only'!N20-Graphics!B$40 -> -15.83828 | C41: ='Analysis-AMY only'!N44-Graphics!C$40 -> 423.41758 | D41: ='Analysis-AMY only'!N14-Graphics!D$40 -> 121.89973 | E41: ='Analysis-AMY only'!N8-Graphics!E$40 -> -4.7074515
A42: =A41+1 -> 2019 | B42: ='Analysis-AMY only'!N21-Graphics!B$40 -> -92.212936 | C42: ='Analysis-AMY only'!N45-Graphics!C$40 -> 130.09127 | D42: ='Analysis-AMY only'!N15-Graphics!D$40 -> -430.38282 | E42: ='Analysis-AMY only'!N9-Graphics!E$40 -> -202.01632
A43: =A42+1 -> 2020 | B43: ='Analysis-AMY only'!N22-Graphics!B$40 -> 46.554968 | C43: ='Analysis-AMY only'!N46-Graphics!C$40 -> -26.475796 | D43: ='Analysis-AMY only'!N16-Graphics!D$40 -> 648.40954 | E43: ='Analysis-AMY only'!N10-Graphics!E$40 -> 595.44446
A44: =A43+1 -> 2021 | B44: ='Analysis-AMY only'!N23-Graphics!B$40 -> 15.83828 | C44: ='Analysis-AMY only'!N47-Graphics!C$40 -> 26.475796 | D44: ='Analysis-AMY only'!N17-Graphics!D$40 -> -121.89973 | E44: ='Analysis-AMY only'!N11-Graphics!E$40 -> 4.7074515
...

Sheet pv_only
A1: state_long | B1: state_short | C1: utility | D1: building_id | E1: latitude | F1: longitude | G1: year | H1: run_type | I1: savings_year1 | J1: annual_energy | K1: npv | L1: year_1_bill | M1: annual_load
A2: alabama | B2: AL | C2: apc | D2: 46496 | E2: 33.56 | F2: -86.75 | G2: 2018 | H2: tmy | I2: 823.29277 | J2: 9041.8682 | K2: -13137.895 | L2: 1084.9327 | M2: 11472.695
A3: alabama | B3: AL | C3: apc | D3: 46496 | E3: 33.56 | F3: -86.75 | G3: 2018 | H3: amy | I3: 822.24787 | J3: 8621.1306 | K3: -13159.448 | L3: 1085.9776 | M3: 11472.695
A4: alabama | B4: AL | C4: apc | D4: 46496 | E4: 33.56 | F4: -86.75 | G4: 2019 | H4: tmy | I4: 830.35446 | J4: 9041.8682 | K4: -13061.853 | L4: 1160.0128 | M4: 11894.363
A5: alabama | B5: AL | C5: apc | D5: 46496 | E5: 33.56 | F5: -86.75 | G5: 2019 | H5: amy | I5: 844.01502 | J5: 8716.7444 | K5: -12909.086 | L5: 1146.3522 | M5: 11894.363
A6: alabama | B6: AL | C6: apc | D6: 46496 | E6: 33.56 | F6: -86.75 | G6: 2020 | H6: tmy | I6: 784.22013 | J6: 9041.8682 | K6: -13581.195 | L6: 946.96551 | M6: 10144.622
A7: alabama | B7: AL | C7: apc | D7: 46496 | E7: 33.56 | F7: -86.75 | G7: 2020 | H7: amy | I7: 786.96201 | J7: 8634.7381 | K7: -13558.2 | L7: 944.22363 | M7: 10144.622
A8: alabama | B8: AL | C8: apc | D8: 46496 | E8: 33.56 | F8: -86.75 | G8: 2021 | H8: tmy | I8: 777.19307 | J8: 9041.8682 | K8: -13653.71 | L8: 831.29847 | M8: 9454.1004
A9: alabama | B9: AL | C9: apc | D9: 46496 | E9: 33.56 | F9: -86.75 | G9: 2021 | H9: amy | I9: 767.47674 | J9: 8847.2704 | K9: -13767.589 | L9: 841.0148 | M9: 9454.1004
A10: alabama | B10: AL | C10: apc | D10: 46496 | E10: 33.56 | F10: -86.75 | G10: 2022 | H10: tmy | I10: 820.24182 | J10: 9041.8682 | K10: -13175.863 | L10: 1064.6844 | M10: 11166.917
A11: alabama | B11: AL | C11: apc | D11: 46496 | E11: 33.56 | F11: -86.75 | G11: 2022 | H11: amy | I11: 870.89925 | J11: 9524.5165 | K11: -12586.969 | L11: 1014.0269 | M11: 11166.917
A12: alabama | B12: AL | C12: apc | D12: 46496 | E12: 33.56 | F12: -86.75 | G12: 2023 | H12: tmy | I12: 810.03416 | J12: 9041.8682 | K12: -13289.117 | L12: 1038.5093 | M12: 10870.759
A13: alabama | B13: AL | C13: apc | D13: 46496 | E13: 33.56 | F13: -86.75 | G13: 2023 | H13: amy | I13: 844.2987 | J13: 9250.2634 | K13: -12894.364 | L13: 1004.2448 | M13: 10870.759
... A145: wisconsin | B145: WI | C145: we_energies | D145: 467842 | E145: 42.95 | F145: -87.9 | G145: 2023 | H145: amy | I145: 1353.0336 | J145: 8143.4266 | K145: -7035.7196 | L145: 490.19945 | M145: 10714.602

Sheet pv_plus_batt
A1: state_long | B1: state_short | C1: utility | D1: building_id | E1: latitude | F1: longitude | G1: year | H1: run_type | I1: savings_year1 | J1: annual_energy | K1: npv | L1: year_1_bill | M1: annual_energy
A2: alabama | B2: AL | C2: apc | D2: 46496 | E2: 33.56 | F2: -86.75 | G2: 2018 | H2: tmy | I2: 994.17436 | J2: 8893.0535 | K2: -11318.081 | L2: 914.05113 | M2: 11472.695
A3: alabama | B3: AL | C3: apc | D3: 46496 | E3: 33.56 | F3: -86.75 | G3: 2018 | H3: amy | I3: 978.21772 | J3: 8488.8643 | K3: -11468.075 | L3: 930.00777 | M3: 11472.695
A4: alabama | B4: AL | C4: apc | D4: 46496 | E4: 33.56 | F4: -86.75 | G4: 2019 | H4: tmy | I4: 998.44839 | J4: 8891.4772 | K4: -11243.75 | L4: 991.91886 | M4: 11894.363
A5: alabama | B5: AL | C5: apc | D5: 46496 | E5: 33.56 | F5: -86.75 | G5: 2019 | H5: amy | I5: 997.14429 | J5: 8578.6294 | K5: -11261.25 | L5: 993.22296 | M5: 11894.363
A6: alabama | B6: AL | C6: apc | D6: 46496 | E6: 33.56 | F6: -86.75 | G6: 2020 | H6: tmy | I6: 979.25769 | J6: 8879.8947 | K6: -11508.348 | L6: 751.92795 | M6: 10144.622
A7: alabama | B7: AL | C7: apc | D7: 46496 | E7: 33.56 | F7: -86.75 | G7: 2020 | H7: amy | I7: 973.85643 | J7: 8483.8302 | K7: -11554.037 | L7: 757.32921 | M7: 10144.622
A8: alabama | B8: AL | C8: apc | D8: 46496 | E8: 33.56 | F8: -86.75 | G8: 2021 | H8: tmy | I8: 993.54796 | J8: 8867.862 | K8: -11374.97 | L8: 614.94358 | M8: 9454.1004
A9: alabama | B9: AL | C9: apc | D9: 46496 | E9: 33.56 | F9: -86.75 | G9: 2021 | H9: amy | I9: 980.78652 | J9: 8679.9579 | K9: -11505.94 | L9: 627.70502 | M9: 9454.1004
A10: alabama | B10: AL | C10: apc | D10: 46496 | E10: 33.56 | F10: -86.75 | G10: 2022 | H10: tmy | I10: 1009.8847 | J10: 8884.3899 | K10: -11131.131 | L10: 875.04147 | M10: 11166.917
A11: alabama | B11: AL | C11: apc | D11: 46496 | E11: 33.56 | F11: -86.75 | G11: 2022 | H11: amy | I11: 1054.4249 | J11: 9365.9185 | K11: -10628.543 | L11: 830.50127 | M11: 11166.917
A12: alabama | B12: AL | C12: apc | D12: 46496 | E12: 33.56 | F12: -86.75 | G12: 2023 | H12: tmy | I12: 1003.4162 | J12: 8879.5458 | K12: -11225.358 | L12: 845.12725 | M12: 10870.759
A13: alabama | B13: AL | C13: apc | D13: 46496 | E13: 33.56 | F13: -86.75 | G13: 2023 | H13: amy | I13: 1048.876 | J13: 9082.9753 | K13: -10712.161 | L13: 799.66747 | M13: 10870.759
... A145: wisconsin | B145: WI | C145: we_energies | D145: 467842 | E145: 42.95 | F145: -87.9 | G145: 2023 | H145: amy | I145: 1353.7599 | J145: 8141.3066 | K145: -7032.0166 | L145: 489.47315 | M145: 10714.602
